2021-10-21 00:00:50,926 Downloading artifact
[34m[1mwandb[39m[22m: [32m[41mERROR[39m[49m Attempted to fetch artifact without alias (e.g. "<artifact_name>:v3" or "<artifact_name>:latest")
Traceback (most recent call last):
  File "/Users/obara/miniforge3/envs/mlflow-97b47f4186030bf5be77fe7f2360fc914fd76376/lib/python3.9/site-packages/wandb/apis/public.py", line 3290, in _load
    response = self.client.execute(
  File "/Users/obara/miniforge3/envs/mlflow-97b47f4186030bf5be77fe7f2360fc914fd76376/lib/python3.9/site-packages/wandb/sdk/lib/retry.py", line 159, in wrapped_fn
    return retrier(*args, **kargs)
  File "/Users/obara/miniforge3/envs/mlflow-97b47f4186030bf5be77fe7f2360fc914fd76376/lib/python3.9/site-packages/wandb/sdk/lib/retry.py", line 102, in __call__
    result = self._call_fn(*args, **kwargs)
  File "/Users/obara/miniforge3/envs/mlflow-97b47f4186030bf5be77fe7f2360fc914fd76376/lib/python3.9/site-packages/wandb/apis/public.py", line 179, in execute
    return self._client.execute(*args, **kwargs)
  File "/Users/obara/miniforge3/envs/mlflow-97b47f4186030bf5be77fe7f2360fc914fd76376/lib/python3.9/site-packages/wandb/vendor/gql-0.2.0/gql/client.py", line 52, in execute
    result = self._get_result(document, *args, **kwargs)
  File "/Users/obara/miniforge3/envs/mlflow-97b47f4186030bf5be77fe7f2360fc914fd76376/lib/python3.9/site-packages/wandb/vendor/gql-0.2.0/gql/client.py", line 60, in _get_result
    return self.transport.execute(document, *args, **kwargs)
  File "/Users/obara/miniforge3/envs/mlflow-97b47f4186030bf5be77fe7f2360fc914fd76376/lib/python3.9/site-packages/wandb/vendor/gql-0.2.0/gql/transport/requests.py", line 39, in execute
    request.raise_for_status()
  File "/Users/obara/miniforge3/envs/mlflow-97b47f4186030bf5be77fe7f2360fc914fd76376/lib/python3.9/site-packages/requests/models.py", line 953, in raise_for_status
    raise HTTPError(http_error_msg, response=self)
requests.exceptions.HTTPError: 400 Client Error: Bad Request for url: https://api.wandb.ai/graphql
During handling of the above exception, another exception occurred:
Traceback (most recent call last):
  File "/Users/obara/miniforge3/envs/mlflow-97b47f4186030bf5be77fe7f2360fc914fd76376/lib/python3.9/site-packages/wandb/apis/normalize.py", line 24, in wrapper
    return func(*args, **kwargs)
  File "/Users/obara/miniforge3/envs/mlflow-97b47f4186030bf5be77fe7f2360fc914fd76376/lib/python3.9/site-packages/wandb/apis/public.py", line 565, in artifact
    artifact = Artifact(self.client, entity, project, artifact_name)
  File "/Users/obara/miniforge3/envs/mlflow-97b47f4186030bf5be77fe7f2360fc914fd76376/lib/python3.9/site-packages/wandb/apis/public.py", line 2824, in __init__
    self._load()
  File "/Users/obara/miniforge3/envs/mlflow-97b47f4186030bf5be77fe7f2360fc914fd76376/lib/python3.9/site-packages/wandb/apis/public.py", line 3302, in _load
    raise ValueError(
ValueError: Attempted to fetch artifact without alias (e.g. "<artifact_name>:v3" or "<artifact_name>:latest")
During handling of the above exception, another exception occurred:
Traceback (most recent call last):
  File "/Users/obara/nd0821-c2-build-model-workflow-exercises/lesson-5-final-pipeline-release-and-deploy/exercises/exercise_14/starter/preprocess/run.py", line 80, in <module>
    go(args)
  File "/Users/obara/nd0821-c2-build-model-workflow-exercises/lesson-5-final-pipeline-release-and-deploy/exercises/exercise_14/starter/preprocess/run.py", line 19, in go
    artifact = run.use_artifact(args.input_artifact)
  File "/Users/obara/miniforge3/envs/mlflow-97b47f4186030bf5be77fe7f2360fc914fd76376/lib/python3.9/site-packages/wandb/sdk/wandb_run.py", line 2088, in use_artifact
    artifact = public_api.artifact(type=type, name=name)
  File "/Users/obara/miniforge3/envs/mlflow-97b47f4186030bf5be77fe7f2360fc914fd76376/lib/python3.9/site-packages/wandb/apis/normalize.py", line 62, in wrapper
    six.reraise(CommError, CommError(message, err), sys.exc_info()[2])
  File "/Users/obara/miniforge3/envs/mlflow-97b47f4186030bf5be77fe7f2360fc914fd76376/lib/python3.9/site-packages/six.py", line 718, in reraise
    raise value.with_traceback(tb)
  File "/Users/obara/miniforge3/envs/mlflow-97b47f4186030bf5be77fe7f2360fc914fd76376/lib/python3.9/site-packages/wandb/apis/normalize.py", line 24, in wrapper
    return func(*args, **kwargs)
  File "/Users/obara/miniforge3/envs/mlflow-97b47f4186030bf5be77fe7f2360fc914fd76376/lib/python3.9/site-packages/wandb/apis/public.py", line 565, in artifact
    artifact = Artifact(self.client, entity, project, artifact_name)
  File "/Users/obara/miniforge3/envs/mlflow-97b47f4186030bf5be77fe7f2360fc914fd76376/lib/python3.9/site-packages/wandb/apis/public.py", line 2824, in __init__
    self._load()
  File "/Users/obara/miniforge3/envs/mlflow-97b47f4186030bf5be77fe7f2360fc914fd76376/lib/python3.9/site-packages/wandb/apis/public.py", line 3302, in _load
    raise ValueError(
wandb.errors.CommError: Attempted to fetch artifact without alias (e.g. "<artifact_name>:v3" or "<artifact_name>:latest")